2024-02-23 17:54:57,157 INFO: Microblog startup [in C:\Users\admin\Downloads\20240223From16To18\m3-week-06-JackDaTsai\m3-week-06-JackDaTsai\app\__init__.py:43]
2024-02-23 17:55:15,070 ERROR: Exception on /edit_profile [POST] [in C:\Users\admin\anaconda3\envs\CodeShibaGo\Lib\site-packages\flask\app.py:828]
Traceback (most recent call last):
  File "C:\Users\admin\anaconda3\envs\CodeShibaGo\Lib\site-packages\sqlalchemy\engine\base.py", line 1960, in _exec_single_context
    self.dialect.do_execute(
  File "C:\Users\admin\anaconda3\envs\CodeShibaGo\Lib\site-packages\sqlalchemy\engine\default.py", line 924, in do_execute
    cursor.execute(statement, parameters)
  File "C:\Users\admin\anaconda3\envs\CodeShibaGo\Lib\site-packages\pymysql\cursors.py", line 153, in execute
    result = self._query(query)
             ^^^^^^^^^^^^^^^^^^
  File "C:\Users\admin\anaconda3\envs\CodeShibaGo\Lib\site-packages\pymysql\cursors.py", line 322, in _query
    conn.query(q)
  File "C:\Users\admin\anaconda3\envs\CodeShibaGo\Lib\site-packages\pymysql\connections.py", line 558, in query
    self._affected_rows = self._read_query_result(unbuffered=unbuffered)
                          ^^^^^^^^^^^^^^^^^^^^^^^^^^^^^^^^^^^^^^^^^^^^^^
  File "C:\Users\admin\anaconda3\envs\CodeShibaGo\Lib\site-packages\pymysql\connections.py", line 822, in _read_query_result
    result.read()
  File "C:\Users\admin\anaconda3\envs\CodeShibaGo\Lib\site-packages\pymysql\connections.py", line 1200, in read
    first_packet = self.connection._read_packet()
                   ^^^^^^^^^^^^^^^^^^^^^^^^^^^^^^
  File "C:\Users\admin\anaconda3\envs\CodeShibaGo\Lib\site-packages\pymysql\connections.py", line 772, in _read_packet
    packet.raise_for_error()
  File "C:\Users\admin\anaconda3\envs\CodeShibaGo\Lib\site-packages\pymysql\protocol.py", line 221, in raise_for_error
    err.raise_mysql_exception(self._data)
  File "C:\Users\admin\anaconda3\envs\CodeShibaGo\Lib\site-packages\pymysql\err.py", line 143, in raise_mysql_exception
    raise errorclass(errno, errval)
pymysql.err.IntegrityError: (1062, "Duplicate entry 'root' for key 'user.ix_user_username'")

The above exception was the direct cause of the following exception:

Traceback (most recent call last):
  File "C:\Users\admin\anaconda3\envs\CodeShibaGo\Lib\site-packages\flask\app.py", line 1463, in wsgi_app
    response = self.full_dispatch_request()
               ^^^^^^^^^^^^^^^^^^^^^^^^^^^^
  File "C:\Users\admin\anaconda3\envs\CodeShibaGo\Lib\site-packages\flask\app.py", line 872, in full_dispatch_request
    rv = self.handle_user_exception(e)
         ^^^^^^^^^^^^^^^^^^^^^^^^^^^^^
  File "C:\Users\admin\anaconda3\envs\CodeShibaGo\Lib\site-packages\flask\app.py", line 870, in full_dispatch_request
    rv = self.dispatch_request()
         ^^^^^^^^^^^^^^^^^^^^^^^
  File "C:\Users\admin\anaconda3\envs\CodeShibaGo\Lib\site-packages\flask\app.py", line 855, in dispatch_request
    return self.ensure_sync(self.view_functions[rule.endpoint])(**view_args)  # type: ignore[no-any-return]
           ^^^^^^^^^^^^^^^^^^^^^^^^^^^^^^^^^^^^^^^^^^^^^^^^^^^^^^^^^^^^^^^^^
  File "C:\Users\admin\anaconda3\envs\CodeShibaGo\Lib\site-packages\flask_login\utils.py", line 290, in decorated_view
    return current_app.ensure_sync(func)(*args, **kwargs)
           ^^^^^^^^^^^^^^^^^^^^^^^^^^^^^^^^^^^^^^^^^^^^^^
  File "C:\Users\admin\Downloads\20240223From16To18\m3-week-06-JackDaTsai\m3-week-06-JackDaTsai\app\routes.py", line 93, in edit_profile
    db.session.commit()
  File "C:\Users\admin\anaconda3\envs\CodeShibaGo\Lib\site-packages\sqlalchemy\orm\scoping.py", line 597, in commit
    return self._proxied.commit()
           ^^^^^^^^^^^^^^^^^^^^^^
  File "C:\Users\admin\anaconda3\envs\CodeShibaGo\Lib\site-packages\sqlalchemy\orm\session.py", line 1972, in commit
    trans.commit(_to_root=True)
  File "<string>", line 2, in commit
  File "C:\Users\admin\anaconda3\envs\CodeShibaGo\Lib\site-packages\sqlalchemy\orm\state_changes.py", line 139, in _go
    ret_value = fn(self, *arg, **kw)
                ^^^^^^^^^^^^^^^^^^^^
  File "C:\Users\admin\anaconda3\envs\CodeShibaGo\Lib\site-packages\sqlalchemy\orm\session.py", line 1257, in commit
    self._prepare_impl()
  File "<string>", line 2, in _prepare_impl
  File "C:\Users\admin\anaconda3\envs\CodeShibaGo\Lib\site-packages\sqlalchemy\orm\state_changes.py", line 139, in _go
    ret_value = fn(self, *arg, **kw)
                ^^^^^^^^^^^^^^^^^^^^
  File "C:\Users\admin\anaconda3\envs\CodeShibaGo\Lib\site-packages\sqlalchemy\orm\session.py", line 1232, in _prepare_impl
    self.session.flush()
  File "C:\Users\admin\anaconda3\envs\CodeShibaGo\Lib\site-packages\sqlalchemy\orm\session.py", line 4296, in flush
    self._flush(objects)
  File "C:\Users\admin\anaconda3\envs\CodeShibaGo\Lib\site-packages\sqlalchemy\orm\session.py", line 4431, in _flush
    with util.safe_reraise():
  File "C:\Users\admin\anaconda3\envs\CodeShibaGo\Lib\site-packages\sqlalchemy\util\langhelpers.py", line 146, in __exit__
    raise exc_value.with_traceback(exc_tb)
  File "C:\Users\admin\anaconda3\envs\CodeShibaGo\Lib\site-packages\sqlalchemy\orm\session.py", line 4392, in _flush
    flush_context.execute()
  File "C:\Users\admin\anaconda3\envs\CodeShibaGo\Lib\site-packages\sqlalchemy\orm\unitofwork.py", line 466, in execute
    rec.execute(self)
  File "C:\Users\admin\anaconda3\envs\CodeShibaGo\Lib\site-packages\sqlalchemy\orm\unitofwork.py", line 642, in execute
    util.preloaded.orm_persistence.save_obj(
  File "C:\Users\admin\anaconda3\envs\CodeShibaGo\Lib\site-packages\sqlalchemy\orm\persistence.py", line 85, in save_obj
    _emit_update_statements(
  File "C:\Users\admin\anaconda3\envs\CodeShibaGo\Lib\site-packages\sqlalchemy\orm\persistence.py", line 912, in _emit_update_statements
    c = connection.execute(
        ^^^^^^^^^^^^^^^^^^^
  File "C:\Users\admin\anaconda3\envs\CodeShibaGo\Lib\site-packages\sqlalchemy\engine\base.py", line 1408, in execute
    return meth(
           ^^^^^
  File "C:\Users\admin\anaconda3\envs\CodeShibaGo\Lib\site-packages\sqlalchemy\sql\elements.py", line 513, in _execute_on_connection
    return connection._execute_clauseelement(
           ^^^^^^^^^^^^^^^^^^^^^^^^^^^^^^^^^^
  File "C:\Users\admin\anaconda3\envs\CodeShibaGo\Lib\site-packages\sqlalchemy\engine\base.py", line 1630, in _execute_clauseelement
    ret = self._execute_context(
          ^^^^^^^^^^^^^^^^^^^^^^
  File "C:\Users\admin\anaconda3\envs\CodeShibaGo\Lib\site-packages\sqlalchemy\engine\base.py", line 1839, in _execute_context
    return self._exec_single_context(
           ^^^^^^^^^^^^^^^^^^^^^^^^^^
  File "C:\Users\admin\anaconda3\envs\CodeShibaGo\Lib\site-packages\sqlalchemy\engine\base.py", line 1979, in _exec_single_context
    self._handle_dbapi_exception(
  File "C:\Users\admin\anaconda3\envs\CodeShibaGo\Lib\site-packages\sqlalchemy\engine\base.py", line 2335, in _handle_dbapi_exception
    raise sqlalchemy_exception.with_traceback(exc_info[2]) from e
  File "C:\Users\admin\anaconda3\envs\CodeShibaGo\Lib\site-packages\sqlalchemy\engine\base.py", line 1960, in _exec_single_context
    self.dialect.do_execute(
  File "C:\Users\admin\anaconda3\envs\CodeShibaGo\Lib\site-packages\sqlalchemy\engine\default.py", line 924, in do_execute
    cursor.execute(statement, parameters)
  File "C:\Users\admin\anaconda3\envs\CodeShibaGo\Lib\site-packages\pymysql\cursors.py", line 153, in execute
    result = self._query(query)
             ^^^^^^^^^^^^^^^^^^
  File "C:\Users\admin\anaconda3\envs\CodeShibaGo\Lib\site-packages\pymysql\cursors.py", line 322, in _query
    conn.query(q)
  File "C:\Users\admin\anaconda3\envs\CodeShibaGo\Lib\site-packages\pymysql\connections.py", line 558, in query
    self._affected_rows = self._read_query_result(unbuffered=unbuffered)
                          ^^^^^^^^^^^^^^^^^^^^^^^^^^^^^^^^^^^^^^^^^^^^^^
  File "C:\Users\admin\anaconda3\envs\CodeShibaGo\Lib\site-packages\pymysql\connections.py", line 822, in _read_query_result
    result.read()
  File "C:\Users\admin\anaconda3\envs\CodeShibaGo\Lib\site-packages\pymysql\connections.py", line 1200, in read
    first_packet = self.connection._read_packet()
                   ^^^^^^^^^^^^^^^^^^^^^^^^^^^^^^
  File "C:\Users\admin\anaconda3\envs\CodeShibaGo\Lib\site-packages\pymysql\connections.py", line 772, in _read_packet
    packet.raise_for_error()
  File "C:\Users\admin\anaconda3\envs\CodeShibaGo\Lib\site-packages\pymysql\protocol.py", line 221, in raise_for_error
    err.raise_mysql_exception(self._data)
  File "C:\Users\admin\anaconda3\envs\CodeShibaGo\Lib\site-packages\pymysql\err.py", line 143, in raise_mysql_exception
    raise errorclass(errno, errval)
sqlalchemy.exc.IntegrityError: (pymysql.err.IntegrityError) (1062, "Duplicate entry 'root' for key 'user.ix_user_username'")
[SQL: UPDATE user SET username=%(username)s, about_me=%(about_me)s WHERE user.id = %(user_id)s]
[parameters: {'username': 'root', 'about_me': 'About me', 'user_id': 2}]
(Background on this error at: https://sqlalche.me/e/20/gkpj)
2024-02-27 17:38:05,044 INFO: Microblog startup [in C:\Users\admin\Downloads\20240227From1600To1830\m3-week-07\m3-week-07-JackDaTsai\microblog\app\__init__.py:46]
2024-02-27 17:48:43,893 INFO: Microblog startup [in C:\Users\admin\Downloads\20240227From1600To1830\m3-week-07\m3-week-07-JackDaTsai\microblog\app\__init__.py:46]
2024-02-27 17:48:58,198 INFO: Microblog startup [in C:\Users\admin\Downloads\20240227From1600To1830\m3-week-07\m3-week-07-JackDaTsai\microblog\app\__init__.py:46]
2024-02-27 17:49:06,234 INFO: Microblog startup [in C:\Users\admin\Downloads\20240227From1600To1830\m3-week-07\m3-week-07-JackDaTsai\microblog\app\__init__.py:46]
